{
    DataVersion: 3955,
    size: [8, 5, 11],
    data: [
        {pos: [3, 0, 3], state: "minecraft:glass"},
        {pos: [3, 0, 4], state: "minecraft:glass"},
        {pos: [3, 0, 5], state: "minecraft:glass"},
        {pos: [3, 0, 6], state: "minecraft:glass"},
        {pos: [3, 0, 7], state: "minecraft:glass"},
        {pos: [4, 0, 3], state: "minecraft:glass"},
        {pos: [4, 0, 4], state: "minecraft:glass"},
        {pos: [4, 0, 5], state: "minecraft:glass"},
        {pos: [4, 0, 6], state: "minecraft:glass"},
        {pos: [4, 0, 7], state: "minecraft:glass"},
        {pos: [5, 0, 3], state: "minecraft:glass"},
        {pos: [5, 0, 4], state: "minecraft:glass"},
        {pos: [5, 0, 5], state: "minecraft:glass"},
        {pos: [5, 0, 6], state: "minecraft:glass"},
        {pos: [5, 0, 7], state: "minecraft:glass"},
        {pos: [6, 0, 3], state: "minecraft:glass"},
        {pos: [6, 0, 4], state: "minecraft:glass"},
        {pos: [6, 0, 5], state: "minecraft:glass"},
        {pos: [6, 0, 6], state: "minecraft:glass"},
        {pos: [6, 0, 7], state: "minecraft:glass"},
        {pos: [7, 0, 3], state: "minecraft:glass"},
        {pos: [7, 0, 4], state: "minecraft:glass"},
        {pos: [7, 0, 5], state: "minecraft:glass"},
        {pos: [7, 0, 6], state: "minecraft:glass"},
        {pos: [7, 0, 7], state: "minecraft:glass"},
        {pos: [3, 1, 3], state: "minecraft:glass"},
        {pos: [3, 1, 4], state: "minecraft:glass"},
        {pos: [3, 1, 5], state: "minecraft:glass"},
        {pos: [3, 1, 6], state: "minecraft:glass"},
        {pos: [3, 1, 7], state: "minecraft:glass"},
        {pos: [4, 1, 3], state: "minecraft:glass"},
        {pos: [4, 1, 4], state: "minecraft:water{level:5}"},
        {pos: [4, 1, 5], state: "minecraft:water{level:6}"},
        {pos: [4, 1, 6], state: "minecraft:glass"},
        {pos: [4, 1, 7], state: "minecraft:glass"},
        {pos: [5, 1, 3], state: "minecraft:glass"},
        {pos: [5, 1, 4], state: "minecraft:water{level:4}"},
        {pos: [5, 1, 5], state: "create:water_wheel{facing:up}", nbt: {FlowScore: 4, Material: {Name: "minecraft:spruce_planks"}, Network: {AddedCapacity: 32.0f, Capacity: 256.0f, Id: 3573412847557L, Size: 2, Stress: 32.0f}, Owner: [I; 533392874, -1520809187, -1583346699, 1960364870], Speed: 8.0f, id: "create:water_wheel"}},
        {pos: [5, 1, 6], state: "minecraft:water{level:0}"},
        {pos: [5, 1, 7], state: "minecraft:glass"},
        {pos: [6, 1, 3], state: "minecraft:glass"},
        {pos: [6, 1, 4], state: "minecraft:water{level:3}"},
        {pos: [6, 1, 5], state: "minecraft:water{level:2}"},
        {pos: [6, 1, 6], state: "minecraft:water{level:1}"},
        {pos: [6, 1, 7], state: "minecraft:glass"},
        {pos: [7, 1, 3], state: "minecraft:glass"},
        {pos: [7, 1, 4], state: "minecraft:glass"},
        {pos: [7, 1, 5], state: "minecraft:glass"},
        {pos: [7, 1, 6], state: "minecraft:glass"},
        {pos: [7, 1, 7], state: "minecraft:glass"},
        {pos: [5, 2, 5], state: "create:mechanical_bearing{facing:up}", nbt: {Angle: 0.0f, ConnectedToExtraKinetics: 0b, Network: {AddedStress: 4.0f, Capacity: 256.0f, Id: 3573412847557L, Size: 2, Stress: 32.0f}, Owner: [I; 533392874, -1520809187, -1583346699, 1960364870], Running: 0b, ScrollValue: 0, Source: [I; 13, -59, 13], Speed: 8.0f, id: "create:mechanical_bearing"}},
        {pos: [4, 3, 5], state: "create:deployer{axis_along_first:false,facing:west}", nbt: {Filter: {count: 1, id: "minecraft:oak_sapling"}, FilterAmount: 64, HeldItem: {}, Inventory: [], Mode: "USE", Overflow: [], Owner: [I; 533392874, -1520809187, -1583346699, 1960364870], Powered: 0b, Speed: 0.0f, State: "WAITING", Timer: 0, UpTo: 1b, id: "create:deployer"}},
        {pos: [4, 3, 6], state: "create:deployer{axis_along_first:false,facing:west}", nbt: {Filter: {count: 1, id: "minecraft:oak_sapling"}, FilterAmount: 64, HeldItem: {}, Inventory: [], Mode: "USE", Overflow: [], Owner: [I; 533392874, -1520809187, -1583346699, 1960364870], Powered: 0b, Speed: 0.0f, State: "WAITING", Timer: 0, UpTo: 1b, id: "create:deployer"}},
        {pos: [4, 3, 7], state: "create:deployer{axis_along_first:false,facing:west}", nbt: {Filter: {count: 1, id: "minecraft:oak_sapling"}, FilterAmount: 64, HeldItem: {}, Inventory: [], Mode: "USE", Overflow: [], Owner: [I; 533392874, -1520809187, -1583346699, 1960364870], Powered: 0b, Speed: 0.0f, State: "WAITING", Timer: 0, UpTo: 1b, id: "create:deployer"}},
        {pos: [4, 3, 8], state: "create:deployer{axis_along_first:false,facing:west}", nbt: {Filter: {count: 1, id: "minecraft:oak_sapling"}, FilterAmount: 64, HeldItem: {}, Inventory: [], Mode: "USE", Overflow: [], Owner: [I; 533392874, -1520809187, -1583346699, 1960364870], Powered: 0b, Speed: 0.0f, State: "WAITING", Timer: 0, UpTo: 1b, id: "create:deployer"}},
        {pos: [4, 3, 9], state: "create:deployer{axis_along_first:false,facing:west}", nbt: {Filter: {count: 1, id: "minecraft:oak_sapling"}, FilterAmount: 64, HeldItem: {}, Inventory: [], Mode: "USE", Overflow: [], Owner: [I; 533392874, -1520809187, -1583346699, 1960364870], Powered: 0b, Speed: 0.0f, State: "WAITING", Timer: 0, UpTo: 1b, id: "create:deployer"}},
        {pos: [4, 3, 10], state: "create:deployer{axis_along_first:false,facing:west}", nbt: {Filter: {count: 1, id: "minecraft:oak_sapling"}, FilterAmount: 64, HeldItem: {}, Inventory: [], Mode: "USE", Overflow: [], Owner: [I; 533392874, -1520809187, -1583346699, 1960364870], Powered: 0b, Speed: 0.0f, State: "WAITING", Timer: 0, UpTo: 1b, id: "create:deployer"}},
        {pos: [5, 3, 5], state: "create:linear_chassis{axis:x,sticky_bottom:false,sticky_top:false}", nbt: {ScrollValue: 8, id: "create:chassis"}},
        {pos: [5, 3, 6], state: "create:linear_chassis{axis:x,sticky_bottom:false,sticky_top:false}", nbt: {ScrollValue: 8, id: "create:chassis"}},
        {pos: [5, 3, 7], state: "create:linear_chassis{axis:x,sticky_bottom:false,sticky_top:false}", nbt: {ScrollValue: 8, id: "create:chassis"}},
        {pos: [5, 3, 8], state: "create:linear_chassis{axis:x,sticky_bottom:false,sticky_top:false}", nbt: {ScrollValue: 8, id: "create:chassis"}},
        {pos: [5, 3, 9], state: "create:linear_chassis{axis:x,sticky_bottom:false,sticky_top:false}", nbt: {ScrollValue: 8, id: "create:chassis"}},
        {pos: [5, 3, 10], state: "create:linear_chassis{axis:x,sticky_bottom:false,sticky_top:false}", nbt: {ScrollValue: 8, id: "create:chassis"}},
        {pos: [6, 3, 5], state: "create:mechanical_saw{axis_along_first:false,facing:east,flipped:false}", nbt: {Filter: {}, FilterAmount: 64, Inventory: {AppliedRecipe: 0b, Items: [], ProcessingTime: -1.0f, RecipeTime: 0.0f, Size: 32}, NextTick: 0, Owner: [I; 533392874, -1520809187, -1583346699, 1960364870], Progress: 0, RecipeIndex: 0, Speed: 0.0f, UpTo: 1b, cltCurrentInterval: 1, id: "create:saw"}},
        {pos: [6, 3, 6], state: "create:mechanical_saw{axis_along_first:false,facing:east,flipped:false}", nbt: {Filter: {}, FilterAmount: 64, Inventory: {AppliedRecipe: 0b, Items: [], ProcessingTime: -1.0f, RecipeTime: 0.0f, Size: 32}, NextTick: 0, Owner: [I; 533392874, -1520809187, -1583346699, 1960364870], Progress: 0, RecipeIndex: 0, Speed: 0.0f, UpTo: 1b, cltCurrentInterval: 1, id: "create:saw"}},
        {pos: [6, 3, 7], state: "create:mechanical_saw{axis_along_first:false,facing:east,flipped:false}", nbt: {Filter: {}, FilterAmount: 64, Inventory: {AppliedRecipe: 0b, Items: [], ProcessingTime: -1.0f, RecipeTime: 0.0f, Size: 32}, NextTick: 0, Owner: [I; 533392874, -1520809187, -1583346699, 1960364870], Progress: 0, RecipeIndex: 0, Speed: 0.0f, UpTo: 1b, cltCurrentInterval: 1, id: "create:saw"}},
        {pos: [6, 3, 8], state: "create:mechanical_saw{axis_along_first:false,facing:east,flipped:false}", nbt: {Filter: {}, FilterAmount: 64, Inventory: {AppliedRecipe: 0b, Items: [], ProcessingTime: -1.0f, RecipeTime: 0.0f, Size: 32}, NextTick: 0, Owner: [I; 533392874, -1520809187, -1583346699, 1960364870], Progress: 0, RecipeIndex: 0, Speed: 0.0f, UpTo: 1b, cltCurrentInterval: 1, id: "create:saw"}},
        {pos: [6, 3, 9], state: "create:mechanical_saw{axis_along_first:false,facing:east,flipped:false}", nbt: {Filter: {}, FilterAmount: 64, Inventory: {AppliedRecipe: 0b, Items: [], ProcessingTime: -1.0f, RecipeTime: 0.0f, Size: 32}, NextTick: 0, Owner: [I; 533392874, -1520809187, -1583346699, 1960364870], Progress: 0, RecipeIndex: 0, Speed: 0.0f, UpTo: 1b, cltCurrentInterval: 1, id: "create:saw"}},
        {pos: [6, 3, 10], state: "create:mechanical_saw{axis_along_first:false,facing:east,flipped:false}", nbt: {Filter: {}, FilterAmount: 64, Inventory: {AppliedRecipe: 0b, Items: [], ProcessingTime: -1.0f, RecipeTime: 0.0f, Size: 32}, NextTick: 0, Owner: [I; 533392874, -1520809187, -1583346699, 1960364870], Progress: 0, RecipeIndex: 0, Speed: 0.0f, UpTo: 1b, cltCurrentInterval: 1, id: "create:saw"}},
        {pos: [5, 4, 9], state: "minecraft:chest{facing:east,type:left,waterlogged:false}", nbt: {Items: [], id: "minecraft:chest"}},
        {pos: [5, 4, 10], state: "minecraft:chest{facing:east,type:right,waterlogged:false}", nbt: {Items: [], id: "minecraft:chest"}}
    ],
    entities: [],
    palette: [
        "minecraft:glass",
        "minecraft:water{level:5}",
        "minecraft:water{level:6}",
        "minecraft:water{level:4}",
        "minecraft:water{level:0}",
        "minecraft:water{level:3}",
        "minecraft:water{level:2}",
        "minecraft:water{level:1}",
        "create:water_wheel{facing:up}",
        "create:mechanical_bearing{facing:up}",
        "create:deployer{axis_along_first:false,facing:west}",
        "create:linear_chassis{axis:x,sticky_bottom:false,sticky_top:false}",
        "create:mechanical_saw{axis_along_first:false,facing:east,flipped:false}",
        "minecraft:chest{facing:east,type:left,waterlogged:false}",
        "minecraft:chest{facing:east,type:right,waterlogged:false}"
    ],
    Railways_DataVersion: 2
}